Workbook

Sheet Data
A1: Order_ID | B1: Customer_ID | C1: Product_ID | D1: Category | E1: Sub_Category | F1: Brand | G1: Quantity | H1: Unit_Price | I1: Discount | J1: Sales | K1: Profit | L1: Rating | M1: Order_Date | N1: Region | O1: Payment_Mode | P1: Profit_Margin_Pct
A2: FK0001 | B2: C563 | C2: P3961 | D2: Electronics | E2: Headphones | F2: Boat | G2: 1 | H2: 1076.32 | I2: 0.2 | J2: 861.06 | K2: 128.36 | L2: 1.9 | M2: 45502 | N2: East | O2: Debit Card | P2: 0.14907207
A3: FK0002 | B3: C812 | C3: P6384 | D3: Fashion | E3: Bags | F3: Wildcraft | G3: 5 | H3: 6269.73 | I3: 0.15 | J3: 26646.35 | K3: 1463.18 | L3: 1.9 | M3: 45317 | N3: South | O3: Net Banking | P3: 0.054911085
A4: FK0003 | B4: C937 | C4: P1678 | D4: Electronics | E4: Cameras | F4: Canon | G4: 1 | H4: 18121.88 | I4: 0 | J4: 18121.88 | K4: 2136 | L4: 1.6 | M4: 45135 | N4: South | O4: Debit Card | P4: 0.11786857
A5: FK0004 | B5: C340 | C5: P3602 | D5: Home & Kitchen | E5: Bedding | F5: Springfit | G5: 3 | H5: 6884.74 | I5: 0.2 | J5: 16523.38 | K5: 3406.58 | L5: 3.6 | M5: 45379 | N5: West | O5: UPI | P5: 0.20616726
A6: FK0005 | B6: C394 | C6: P4059 | D6: Fashion | E6: Watches | F6: Titan | G6: 5 | H6: 4008.84 | I6: 0.1 | J6: 18039.78 | K6: 3729.67 | L6: 4.3 | M6: 45532 | N6: South | O6: Debit Card | P6: 0.20674698
A7: FK0006 | B7: C708 | C7: P7129 | D7: Beauty | E7: Makeup | F7: Lakme | G7: 4 | H7: 18812.78 | I7: 0 | J7: 75251.12 | K7: 14285.79 | L7: 1.9 | M7: 45386 | N7: North | O7: Credit Card | P7: 0.18984156
A8: FK0007 | B8: C663 | C8: P5865 | D8: Fashion | E8: Bags | F8: Wildcraft | G8: 3 | H8: 199.23 | I8: 0.1 | J8: 537.92 | K8: 92.18 | L8: 1.4 | M8: 44938 | N8: North | O8: Net Banking | P8: 0.17136377
A9: FK0008 | B9: C272 | C9: P5628 | D9: Fashion | E9: Watches | F9: Fossil | G9: 1 | H9: 16114.74 | I9: 0.15 | J9: 13697.53 | K9: 2363.08 | L9: 2.3 | M9: 45148 | N9: South | O9: Debit Card | P9: 0.17251869
A10: FK0009 | B10: C494 | C10: P1300 | D10: Beauty | E10: Makeup | F10: Lakme | G10: 5 | H10: 17717.7 | I10: 0.15 | J10: 75300.22 | K10: 7148.1 | L10: 1.6 | M10: 45522 | N10: North | O10: Debit Card | P10: 0.09492801
A11: FK0010 | B11: C817 | C11: P1400 | D11: Beauty | E11: Fragrances | F11: Axe | G11: 5 | H11: 13935.58 | I11: 0.2 | J11: 55742.32 | K11: 13213.16 | L11: 3.2 | M11: 45500 | N11: West | O11: Cash on Delivery | P11: 0.23704001
A12: FK0011 | B12: C105 | C12: P6946 | D12: Fashion | E12: Watches | F12: Casio | G12: 5 | H12: 14369.47 | I12: 0.15 | J12: 61070.25 | K12: 11409.75 | L12: 4.3 | M12: 45385 | N12: North | O12: Net Banking | P12: 0.18682992
A13: FK0012 | B13: C706 | C13: P9256 | D13: Home & Kitchen | E13: Decor | F13: FabIndia | G13: 3 | H13: 17189.97 | I13: 0.15 | J13: 43834.42 | K13: 3530.38 | L13: 1.4 | M13: 45553 | N13: East | O13: UPI | P13: 0.080538992
... A2001: FK2000 | B2001: C543 | C2001: P5128 | D2001: Beauty | E2001: Fragrances | F2001: Axe | G2001: 3 | H2001: 937.77 | I2001: 0.2 | J2001: 2250.65 | K2001: 361.73 | L2001: 3.4 | M2001: 44976 | N2001: West | O2001: Cash on Delivery | P2001: 0.16072246

Sheet Lists
A1: All | B1: All | C1: All
A2: East | B2: Beauty | C2: Adidas
A3: North | B3: Electronics | C3: Apple
A4: South | B4: Fashion | C4: Axe
A5: West | B5: Home & Kitchen | C5: Bajaj
C6: Boat
C7: Bose
C8: Canon
C9: Caprese
C10: Casio
C11: Dell
C12: Duroflex
C13: Engage
C14: FabIndia
C15: Fogg
C16: Fossil
C17: Fujifilm
... C58: Zara

Sheet Calc
A1: Selections | D1: Total Sales | E1: Total Profit | F1: Total Orders | G1: Avg Rating | H1: Profit Margin %
A2: Region | B2: All | D2: =SUMPRODUCT((IF($B$2="All",1,--(Data!$N$2:$N$2001=$B$2)))*(IF($B$3="All",1,--(Data!$D$2:$D$2001=$B$3)))*(IF($B$4="All",1,--(Data!$F$2:$F$2001=$B$4)))*(Data!$J$2:$J$2001)) -> 55434462 | E2: =SUMPRODUCT((IF($B$2="All",1,--(Data!$N$2:$N$2001=$B$2)))*(IF($B$3="All",1,--(Data!$D$2:$D$2001=$B$3)))*(IF($B$4="All",1,--(Data!$F$2:$F$2001=$B$4)))*(Data!$K$2:$K$2001)) -> 8318986 | F2: =SUMPRODUCT((IF($B$2="All",1,--(Data!$N$2:$N$2001=$B$2)))*(IF($B$3="All",1,--(Data!$D$2:$D$2001=$B$3)))*(IF($B$4="All",1,--(Data!$F$2:$F$2001=$B$4)))) -> 1 | G2: =IF(F2=0,0,SUMPRODUCT((IF($B$2="All",1,--(Data!$N$2:$N$2001=$B$2)))*(IF($B$3="All",1,--(Data!$D$2:$D$2001=$B$3)))*(IF($B$4="All",1,--(Data!$F$2:$F$2001=$B$4)))*(Data!$L$2:$L$2001))/F2) -> 5978.7 | H2: =IF(D2=0,0,E2/D2) -> 0.15006885
A3: Category | B3: All
A4: Brand | B4: All
A6: Category | B6: Sub_Category | C6: Total Sales | E6: Brand | F6: Avg Rating | H6: Month | I6: Sales | K6: Top 10 Customers | L6: Revenue
A7: Beauty | B7: Fragrances | C7: =SUMIFS(Data!$J:$J,Data!$D:$D,A7,Data!$E:$E,B7) -> 3094564.9 | E7: Adidas | F7: =AVERAGEIFS(Data!$L:$L,Data!$F:$F,E7) -> 2.6761194 | H7: 44927 | I7: =SUMIFS(Data!$J:$J,Data!$M:$M,">="&H7,Data!$M:$M,"<"&EDATE(H7,1)) -> 2435371.5 | K7: C708 | L7: 398268.79
A8: Beauty | B8: Hair Care | C8: =SUMIFS(Data!$J:$J,Data!$D:$D,A8,Data!$E:$E,B8) -> 3584288 | E8: Apple | F8: =AVERAGEIFS(Data!$L:$L,Data!$F:$F,E8) -> 3.0155172 | H8: 44958 | I8: =SUMIFS(Data!$J:$J,Data!$M:$M,">="&H8,Data!$M:$M,"<"&EDATE(H8,1)) -> 2235738.7 | K8: C553 | L8: 262819.02
A9: Beauty | B9: Makeup | C9: =SUMIFS(Data!$J:$J,Data!$D:$D,A9,Data!$E:$E,B9) -> 3667493 | E9: Axe | F9: =AVERAGEIFS(Data!$L:$L,Data!$F:$F,E9) -> 2.9714286 | H9: 44986 | I9: =SUMIFS(Data!$J:$J,Data!$M:$M,">="&H9,Data!$M:$M,"<"&EDATE(H9,1)) -> 1915572.3 | K9: C568 | L9: 245909.3
A10: Beauty | B10: Skincare | C10: =SUMIFS(Data!$J:$J,Data!$D:$D,A10,Data!$E:$E,B10) -> 3590798.8 | E10: Bajaj | F10: =AVERAGEIFS(Data!$L:$L,Data!$F:$F,E10) -> 3.2103448 | H10: 45017 | I10: =SUMIFS(Data!$J:$J,Data!$M:$M,">="&H10,Data!$M:$M,"<"&EDATE(H10,1)) -> 2438872.9 | K10: C716 | L10: 232551.28
A11: Electronics | B11: Cameras | C11: =SUMIFS(Data!$J:$J,Data!$D:$D,A11,Data!$E:$E,B11) -> 3958378.6 | E11: Boat | F11: =AVERAGEIFS(Data!$L:$L,Data!$F:$F,E11) -> 3.0225 | H11: 45047 | I11: =SUMIFS(Data!$J:$J,Data!$M:$M,">="&H11,Data!$M:$M,"<"&EDATE(H11,1)) -> 2143942.8 | K11: C150 | L11: 229472.59
A12: Electronics | B12: Headphones | C12: =SUMIFS(Data!$J:$J,Data!$D:$D,A12,Data!$E:$E,B12) -> 3189784.7 | E12: Bose | F12: =AVERAGEIFS(Data!$L:$L,Data!$F:$F,E12) -> 3.3375 | H12: 45078 | I12: =SUMIFS(Data!$J:$J,Data!$M:$M,">="&H12,Data!$M:$M,"<"&EDATE(H12,1)) -> 2302547.7 | K12: C550 | L12: 218723.18
A13: Electronics | B13: Laptops | C13: =SUMIFS(Data!$J:$J,Data!$D:$D,A13,Data!$E:$E,B13) -> 2789532.6 | E13: Canon | F13: =AVERAGEIFS(Data!$L:$L,Data!$F:$F,E13) -> 2.6472222 | H13: 45108 | I13: =SUMIFS(Data!$J:$J,Data!$M:$M,">="&H13,Data!$M:$M,"<"&EDATE(H13,1)) -> 2296812.8 | K13: C980 | L13: 218698.02
A14: Electronics | B14: Mobiles | C14: =SUMIFS(Data!$J:$J,Data!$D:$D,A14,Data!$E:$E,B14) -> 3702815.8 | E14: Caprese | F14: =AVERAGEIFS(Data!$L:$L,Data!$F:$F,E14) -> 3.0741935 | H14: 45139 | I14: =SUMIFS(Data!$J:$J,Data!$M:$M,">="&H14,Data!$M:$M,"<"&EDATE(H14,1)) -> 1980991.2 | K14: C640 | L14: 209506.99
A15: Fashion | B15: Apparel | C15: =SUMIFS(Data!$J:$J,Data!$D:$D,A15,Data!$E:$E,B15) -> 2989981.9 | E15: Casio | F15: =AVERAGEIFS(Data!$L:$L,Data!$F:$F,E15) -> 3.1814815 | H15: 45170 | I15: =SUMIFS(Data!$J:$J,Data!$M:$M,">="&H15,Data!$M:$M,"<"&EDATE(H15,1)) -> 2553288.7 | K15: C899 | L15: 208742.62
A16: Fashion | B16: Bags | C16: =SUMIFS(Data!$J:$J,Data!$D:$D,A16,Data!$E:$E,B16) -> 4076618 | E16: Dell | F16: =AVERAGEIFS(Data!$L:$L,Data!$F:$F,E16) -> 2.6758621 | H16: 45200 | I16: =SUMIFS(Data!$J:$J,Data!$M:$M,">="&H16,Data!$M:$M,"<"&EDATE(H16,1)) -> 2592550.3 | K16: C305 | L16: 207609.83
A17: Fashion | B17: Shoes | C17: =SUMIFS(Data!$J:$J,Data!$D:$D,A17,Data!$E:$E,B17) -> 3826204.8 | E17: Duroflex | F17: =AVERAGEIFS(Data!$L:$L,Data!$F:$F,E17) -> 2.6058824 | H17: 45231 | I17: =SUMIFS(Data!$J:$J,Data!$M:$M,">="&H17,Data!$M:$M,"<"&EDATE(H17,1)) -> 2512048.9
A18: Fashion | B18: Watches | C18: =SUMIFS(Data!$J:$J,Data!$D:$D,A18,Data!$E:$E,B18) -> 3306858.1 | E18: Engage | F18: =AVERAGEIFS(Data!$L:$L,Data!$F:$F,E18) -> 2.9884615 | H18: 45261 | I18: =SUMIFS(Data!$J:$J,Data!$M:$M,">="&H18,Data!$M:$M,"<"&EDATE(H18,1)) -> 2647421.6
A19: Home & Kitchen | B19: Bedding | C19: =SUMIFS(Data!$J:$J,Data!$D:$D,A19,Data!$E:$E,B19) -> 3114458.7 | E19: FabIndia | F19: =AVERAGEIFS(Data!$L:$L,Data!$F:$F,E19) -> 3.0757576 | H19: 45292 | I19: =SUMIFS(Data!$J:$J,Data!$M:$M,">="&H19,Data!$M:$M,"<"&EDATE(H19,1)) -> 2858517
A20: Home & Kitchen | B20: Decor | C20: =SUMIFS(Data!$J:$J,Data!$D:$D,A20,Data!$E:$E,B20) -> 3199439.1 | E20: Fogg | F20: =AVERAGEIFS(Data!$L:$L,Data!$F:$F,E20) -> 2.9909091 | H20: 45323 | I20: =SUMIFS(Data!$J:$J,Data!$M:$M,">="&H20,Data!$M:$M,"<"&EDATE(H20,1)) -> 2660784.1
A21: Home & Kitchen | B21: Furniture | C21: =SUMIFS(Data!$J:$J,Data!$D:$D,A21,Data!$E:$E,B21) -> 3830032.8 | E21: Fossil | F21: =AVERAGEIFS(Data!$L:$L,Data!$F:$F,E21) -> 2.9918919 | H21: 45352 | I21: =SUMIFS(Data!$J:$J,Data!$M:$M,">="&H21,Data!$M:$M,"<"&EDATE(H21,1)) -> 2359002.5
A22: Home & Kitchen | B22: Kitchen Appliances | C22: =SUMIFS(Data!$J:$J,Data!$D:$D,A22,Data!$E:$E,B22) -> 3513212.2 | E22: Fujifilm | F22: =AVERAGEIFS(Data!$L:$L,Data!$F:$F,E22) -> 3.1740741 | H22: 45383 | I22: =SUMIFS(Data!$J:$J,Data!$M:$M,">="&H22,Data!$M:$M,"<"&EDATE(H22,1)) -> 1940900.5
E23: Godrej | F23: =AVERAGEIFS(Data!$L:$L,Data!$F:$F,E23) -> 2.7194444 | H23: 45413 | I23: =SUMIFS(Data!$J:$J,Data!$M:$M,">="&H23,Data!$M:$M,"<"&EDATE(H23,1)) -> 2430244.6
E24: H&M | F24: =AVERAGEIFS(Data!$L:$L,Data!$F:$F,E24) -> 3.4 | H24: 45444 | I24: =SUMIFS(Data!$J:$J,Data!$M:$M,">="&H24,Data!$M:$M,"<"&EDATE(H24,1)) -> 2189313.8
E25: HP | F25: =AVERAGEIFS(Data!$L:$L,Data!$F:$F,E25) -> 2.9642857 | H25: 45474 | I25: =SUMIFS(Data!$J:$J,Data!$M:$M,">="&H25,Data!$M:$M,"<"&EDATE(H25,1)) -> 1715218.6
E26: HomeCentre | F26: =AVERAGEIFS(Data!$L:$L,Data!$F:$F,E26) -> 3.1322581 | H26: 45505 | I26: =SUMIFS(Data!$J:$J,Data!$M:$M,">="&H26,Data!$M:$M,"<"&EDATE(H26,1)) -> 2020407.9
E27: HomeTown | F27: =AVERAGEIFS(Data!$L:$L,Data!$F:$F,E27) -> 2.8965517 | H27: 45536 | I27: =SUMIFS(Data!$J:$J,Data!$M:$M,">="&H27,Data!$M:$M,"<"&EDATE(H27,1)) -> 2686924.7
B28: Payment Mode | C28: Total Sales | E28: Ikea | F28: =AVERAGEIFS(Data!$L:$L,Data!$F:$F,E28) -> 2.86 | H28: 45566 | I28: =SUMIFS(Data!$J:$J,Data!$M:$M,">="&H28,Data!$M:$M,"<"&EDATE(H28,1)) -> 1939273.6
B29: Credit Card | C29: 11952568 | E29: JBL | F29: =AVERAGEIFS(Data!$L:$L,Data!$F:$F,E29) -> 2.6761905 | H29: 45597 | I29: =SUMIFS(Data!$J:$J,Data!$M:$M,">="&H29,Data!$M:$M,"<"&EDATE(H29,1)) -> 2591123.4
B30: Cash on Delivery | C30: 11349279 | E30: Kurlon | F30: =AVERAGEIFS(Data!$L:$L,Data!$F:$F,E30) -> 2.612 | H30: 45627 | I30: =SUMIFS(Data!$J:$J,Data!$M:$M,">="&H30,Data!$M:$M,"<"&EDATE(H30,1)) -> 1987591.7
B31: Debit Card | C31: 10768712 | E31: L'Oreal | F31: =AVERAGEIFS(Data!$L:$L,Data!$F:$F,E31) -> 2.8440678
B32: Net Banking | C32: 10694390 | E32: Lakme | F32: =AVERAGEIFS(Data!$L:$L,Data!$F:$F,E32) -> 2.9057143
B33: UPI | C33: 10669512 | E33: Lenovo | F33: =AVERAGEIFS(Data!$L:$L,Data!$F:$F,E33) -> 3.01875
E34: Levi's | F34: =AVERAGEIFS(Data!$L:$L,Data!$F:$F,E34) -> 2.764
E35: MAC | F35: =AVERAGEIFS(Data!$L:$L,Data!$F:$F,E35) -> 3.2
E36: Maybelline | F36: =AVERAGEIFS(Data!$L:$L,Data!$F:$F,E36) -> 2.8441176
E37: Morphy Richards | F37: =AVERAGEIFS(Data!$L:$L,Data!$F:$F,E37) -> 3.1666667
E38: Neutrogena | F38: =AVERAGEIFS(Data!$L:$L,Data!$F:$F,E38) -> 3.05
E39: Nike | F39: =AVERAGEIFS(Data!$L:$L,Data!$F:$F,E39) -> 2.9158416
E40: Nikon | F40: =AVERAGEIFS(Data!$L:$L,Data!$F:$F,E40) -> 2.8967742
E41: Nilkamal | F41: =AVERAGEIFS(Data!$L:$L,Data!$F:$F,E41) -> 3.4
...

Sheet Dashboard
A1: Interactive Sales Dashboard
A4: Filters | E4: Total Sales | H4: Total Profit | K4: Profit Margin
A5: Region | B5: =Calc!B2 -> All | E5: =Calc!D2 -> 55434462 | H5: =Calc!E2 -> 8318986 | K5: =Calc!H2 -> 0.15006885
A6: Category | B6: =Calc!B3 -> All
A7: Brand | B7: =Calc!B4 -> All
E8: Total Orders | H8: Avg Rating
E9: =Calc!F2 -> 1 | H9: =Calc!G2 -> 5978.7

Sheet ChartData
A1: Brand | B1: Avg Rating
A2: H&M | B2: 3.4
A3: Nilkamal | B3: 3.4
A4: Rolex | B4: 3.3461538
A5: Bose | B5: 3.3375
A6: The Body Shop | B6: 3.2517241
A7: Titan | B7: 3.2342857
A8: Zara | B8: 3.2129032
A9: Bajaj | B9: 3.2103448
A10: MAC | B10: 3.2
A11: Casio | B11: 3.1814815
